20110615
========

Hier noch ein Traceback::

  Traceback (most recent call last):
    File "/var/snapshots/django/django/core/handlers/base.py", line 111, in get_response
      response = callback(request, *callback_args, **callback_kwargs)
    File "/var/snapshots/lino/lino/ui/extjs3/ext_ui.py", line 1118, in api_element_view
      error=e)
  UnicodeDecodeError: 'ascii' codec can't decode byte 0xc2 in position 52: ordinal not in range(128)

Und hier der dazugehörige Code::

    try:
        return a.run(ar,elem)
    except Exception,e:
        msg = _("Action %(action)s failed for %(record)s: %(error)s") % dict(
            action=a,
            record=obj2str(elem),
            error=e) ## lino 1118
        logger.warning(msg)
        logger.exception(e)
        return error_response(e,msg)
        
Also fast die gleiche Lektion wie :doc:`vor 2 Wochen <0527>`: 
"When you pass more than one formatting argument to a 
logger function, and one of them is a unicode string, 
then the other argument(s) may not be bytestrings 
containing non-ascii chars."

Mit der Verallgemeinerung, dass das für alle 
String-Formatierungen (Operator ``%``) gilt, und zwar 
sowohl für Positionsargumente wie für Keyword-Argumente.

Der Fehler ist reproduzierbar, indem ich auf 
`Vertrag # 88 
<http://localhost:8080/api/dsbe/Contracts/88?fmt=detail>`_
gehe und dort :guilabel:`Drucken` klicke.

Checkin-Serie 20110615 kommt noch mit nach :doc:`/releases/20110613` rein.

Beim Einchecken und Testen entdecke ich, dass die Sache noch perverser ist als 
gedacht.

Wenn ich die Exception nicht selber abfange, dann tut Django das, 
und der kann es. Der schickt dann dem Benutzer eine freundliche 500-Meldung 
und den Systemverwaltern (`setting:`ADMINS`) eine E-Mail, dank derer 
ich erstmals überhaupt die Exception an sich sehe::

  Traceback (most recent call last):
    File "/var/snapshots/django/django/core/handlers/base.py", line 111, in get_response
      response = callback(request, *callback_args, **callback_kwargs)
    File "/var/snapshots/lino/lino/ui/extjs3/ext_ui.py", line 1111, in api_element_view
      return a.run(ar,elem)
    File "/var/snapshots/lino/lino/mixins/printable.py", line 407, in run
      bm.build(self,elem)
    File "/var/snapshots/lino/lino/mixins/printable.py", line 186, in build
      tpl_leaf = self.get_template_leaf(action,elem)
    File "/var/snapshots/lino/lino/mixins/printable.py", line 162, in get_template_leaf
      tpls = action.get_print_templates(self,elem)
    File "/var/snapshots/lino/lino/mixins/printable.py", line 399, in get_print_templates
      return elem.get_print_templates(bm,self)
    File "/var/snapshots/lino/lino/mixins/printable.py", line 610, in get_print_templates
      (ptype.__class__.__name__,ptype,bm.template_ext))
  Exception: Invalid template configured for ContractType "Art.60§7 intern". Expected filename ending with '.odt'.

Der besagte Code ist::

  if not ptype.template.endswith(bm.template_ext):
      raise Exception(
        "Invalid template configured for %s \"%s\". Expected filename ending with '%s'." %
        (ptype.__class__.__name__,ptype,bm.template_ext))

Also das "§"-Zeichen in "Art.60§7 intern" ist der Auslöser.

Was ich noch nicht wusste: es gibt `Python issue #2517
<http://bugs.python.org/issue2517>`_, : 
Eine `Exception` mit einem Unicode-String führt zumindest in Python 2.6 
noch allgemein an vielen Stellen zu Problemen. 

Lektion : `Exceptions` dürfen ausschließlich ASCII-Code enthalten 
und folglich auch nicht internationalisert sein. Im obigen Beispiel 
reicht::

  if not ptype.template.endswith(bm.template_ext):
      raise Exception(
        "Invalid template configured for %s %r. Expected filename ending with %r." %
        (ptype.__class__.__name__,ptype,bm.template_ext))


Nach mir das klargeworden ist, habe ich noch ein Problemchen


  Traceback (most recent call last):
    File "/var/snapshots/django/django/core/handlers/base.py", line 111, in get_response
      response = callback(request, *callback_args, **callback_kwargs)
    File "/var/snapshots/lino/lino/ui/extjs3/ext_ui.py", line 1115, in api_element_view
      logger.exception(e)
    File "/usr/lib/python2.6/logging/__init__.py", line 1088, in exception
      self.error(*((msg,) + args), **{'exc_info': 1})
    File "/usr/lib/python2.6/logging/__init__.py", line 1082, in error
      self._log(ERROR, msg, args, **kwargs)
    File "/usr/lib/python2.6/logging/__init__.py", line 1173, in _log
      self.handle(record)
    File "/usr/lib/python2.6/logging/__init__.py", line 1183, in handle
      self.callHandlers(record)
    File "/usr/lib/python2.6/logging/__init__.py", line 1220, in callHandlers
      hdlr.handle(record)
    File "/usr/lib/python2.6/logging/__init__.py", line 679, in handle
      self.emit(record)
    File "/var/snapshots/django/django/utils/log.py", line 72, in emit
      mail.mail_admins(subject, message, fail_silently=True, html_message=html_message)
    File "/var/snapshots/django/django/core/mail/__init__.py", line 91, in mail_admins
      mail = EmailMultiAlternatives(u'%s%s' % (settings.EMAIL_SUBJECT_PREFIX, subject),
  UnicodeDecodeError: 'ascii' codec can't decode byte 0xc2 in position 73: ordinal not in range(128)


