/home/luc/hgwork/lino/docs/api/lino.modlib.pages.fixtures.rst:7: WARNING: autodoc: failed to import module u'lino.modlib.pages.fixtures.intro'; the following exception was raised:
Traceback (most recent call last):
  File "/home/luc/pythonenvs/py27/local/lib/python2.7/site-packages/sphinx/ext/autodoc.py", line 326, in import_object
    __import__(self.modname)
  File "/home/luc/hgwork/lino/lino/modlib/pages/fixtures/intro.py", line 52, in <module>
    """)
  File "/home/luc/hgwork/lino/lino/modlib/pages/builder.py", line 38, in page
    obj = pages.lookup(ref,None)
  File "/home/luc/hgwork/lino/lino/modlib/pages/models.py", line 254, in lookup
    return Page.get_by_ref(ref,*args,**kw)
  File "/home/luc/hgwork/lino/lino/mixins/__init__.py", line 757, in get_by_ref
    return cls.objects.get(ref=ref)
  File "/home/luc/pythonenvs/py27/local/lib/python2.7/site-packages/django/db/models/manager.py", line 143, in get
    return self.get_query_set().get(*args, **kwargs)
  File "/home/luc/pythonenvs/py27/local/lib/python2.7/site-packages/django/db/models/query.py", line 382, in get
    num = len(clone)
  File "/home/luc/pythonenvs/py27/local/lib/python2.7/site-packages/django/db/models/query.py", line 90, in __len__
    self._result_cache = list(self.iterator())
  File "/home/luc/pythonenvs/py27/local/lib/python2.7/site-packages/django/db/models/query.py", line 301, in iterator
    for row in compiler.results_iter():
  File "/home/luc/pythonenvs/py27/local/lib/python2.7/site-packages/django/db/models/sql/compiler.py", line 775, in results_iter
    for rows in self.execute_sql(MULTI):
  File "/home/luc/pythonenvs/py27/local/lib/python2.7/site-packages/django/db/models/sql/compiler.py", line 840, in execute_sql
    cursor.execute(sql, params)
  File "/home/luc/pythonenvs/py27/local/lib/python2.7/site-packages/django/db/backends/util.py", line 41, in execute
    return self.cursor.execute(sql, params)
  File "/home/luc/pythonenvs/py27/local/lib/python2.7/site-packages/django/db/backends/sqlite3/base.py", line 366, in execute
    six.reraise(utils.DatabaseError, utils.DatabaseError(*tuple(e.args)), sys.exc_info()[2])
  File "/home/luc/pythonenvs/py27/local/lib/python2.7/site-packages/django/db/backends/sqlite3/base.py", line 362, in execute
    return Database.Cursor.execute(self, query, params)
DatabaseError: no such table: pages_page
/home/luc/hgwork/lino/docs/api/lino.modlib.pages.fixtures.rst:14: WARNING: autodoc: failed to import module u'lino.modlib.pages.fixtures.man'; the following exception was raised:
Traceback (most recent call last):
  File "/home/luc/pythonenvs/py27/local/lib/python2.7/site-packages/sphinx/ext/autodoc.py", line 326, in import_object
    __import__(self.modname)
  File "/home/luc/hgwork/lino/lino/modlib/pages/fixtures/man.py", line 37, in <module>
    """)
  File "/home/luc/hgwork/lino/lino/modlib/pages/builder.py", line 38, in page
    obj = pages.lookup(ref,None)
  File "/home/luc/hgwork/lino/lino/modlib/pages/models.py", line 254, in lookup
    return Page.get_by_ref(ref,*args,**kw)
  File "/home/luc/hgwork/lino/lino/mixins/__init__.py", line 757, in get_by_ref
    return cls.objects.get(ref=ref)
  File "/home/luc/pythonenvs/py27/local/lib/python2.7/site-packages/django/db/models/manager.py", line 143, in get
    return self.get_query_set().get(*args, **kwargs)
  File "/home/luc/pythonenvs/py27/local/lib/python2.7/site-packages/django/db/models/query.py", line 382, in get
    num = len(clone)
  File "/home/luc/pythonenvs/py27/local/lib/python2.7/site-packages/django/db/models/query.py", line 90, in __len__
    self._result_cache = list(self.iterator())
  File "/home/luc/pythonenvs/py27/local/lib/python2.7/site-packages/django/db/models/query.py", line 301, in iterator
    for row in compiler.results_iter():
  File "/home/luc/pythonenvs/py27/local/lib/python2.7/site-packages/django/db/models/sql/compiler.py", line 775, in results_iter
    for rows in self.execute_sql(MULTI):
  File "/home/luc/pythonenvs/py27/local/lib/python2.7/site-packages/django/db/models/sql/compiler.py", line 840, in execute_sql
    cursor.execute(sql, params)
  File "/home/luc/pythonenvs/py27/local/lib/python2.7/site-packages/django/db/backends/util.py", line 41, in execute
    return self.cursor.execute(sql, params)
  File "/home/luc/pythonenvs/py27/local/lib/python2.7/site-packages/django/db/backends/sqlite3/base.py", line 366, in execute
    six.reraise(utils.DatabaseError, utils.DatabaseError(*tuple(e.args)), sys.exc_info()[2])
  File "/home/luc/pythonenvs/py27/local/lib/python2.7/site-packages/django/db/backends/sqlite3/base.py", line 362, in execute
    return Database.Cursor.execute(self, query, params)
DatabaseError: no such table: pages_page
/home/luc/hgwork/lino/docs/todo.rst:33: WARNING: undefined label: welfare.reception.appontmentsbyclient (if the link has no caption the label must precede a section header)
/home/luc/hgwork/lino/docs/todo.rst:37: WARNING: undefined label: welfare.cal.myevents (if the link has no caption the label must precede a section header)
